<?xml version="1.0"?>
<robot name="my_robot">

    <!-- Define materials -->
    <material name="gray">
        <color rgba="0.5 0.5 0.5 1.0"/>
    </material>
    <material name="yellow">
        <color rgba="1.0 1.0 0.0 1.0"/>
    </material>
    <material name="black">
        <color rgba="0.0 0.0 0.0 1.0"/>
    </material>

    <!-- Base Footprint -->
    <link name="base_footprint" />

    <!-- Base Link -->
    <link name="base_link">
        <visual>
            <geometry>
                <box size="3.12 2.06 1.10"/>
            </geometry>
            <material name="gray"/>
        </visual>
        <inertial>
            <mass value="20.0"/>
            <origin xyz="0 0 0" rpy="0 0 0"/>
            <inertia ixx="1.0" ixy="0.0" ixz="0.0" iyy="1.0" iyz="0.0" izz="1.0"/>
        </inertial>
    </link>
    <joint name="base_link_joint" type="fixed">
        <parent link="base_footprint"/>
        <child link="base_link"/>
        <origin xyz="0.0 0.0 1.05" rpy="0.0 0.0 0.0"/>
    </joint>
    <gazebo reference="base_link">
        <material>Gazebo/Gray</material>
    </gazebo>

    <!-- Compartment 1 -->
    <link name="comp_1">
        <visual>
            <geometry>
                <box size="1.64 2.06 1.52"/>
            </geometry>
            <material name="gray"/>
        </visual>
        <inertial>
            <mass value="10.0"/>
            <origin xyz="0 0 0" rpy="0 0 0"/>
            <inertia ixx="0.5" ixy="0.0" ixz="0.0" iyy="0.5" iyz="0.0" izz="0.5"/>
        </inertial>
    </link>
    <joint name="comp_1_joint" type="fixed">
        <parent link="base_link"/>
        <child link="comp_1"/>
        <origin xyz="-0.74 0.0 0.55" rpy="0.0 0.0 0.0"/>
    </joint>
    <gazebo reference="comp_1">
        <material>Gazebo/Gray</material>
    </gazebo>

    <!-- Left Rear Wheel -->
    <link name="left_rear_wheel">
        <visual>
            <geometry>
                <cylinder length="0.26" radius="0.5"/>
            </geometry>
            <material name="black"/>
        </visual>
        <inertial>
            <mass value="2.0"/>
            <origin xyz="0 0 0" rpy="0 0 0"/>
            <inertia ixx="0.1" ixy="0.0" ixz="0.0" iyy="0.1" iyz="0.0" izz="0.1"/>
        </inertial>
    </link>
    <joint name="left_rear_wheel_joint" type="continuous">
        <parent link="base_link"/>
        <child link="left_rear_wheel"/>
        <origin xyz="-1.56 1.16 -0.55" rpy="-1.57 0.0 0.0"/>
        <axis xyz="0 0 1"/>
    </joint>
    <gazebo reference="left_rear_wheel">
        <material>Gazebo/Black</material>
    </gazebo>

    <!-- Right Rear Wheel -->
    <link name="right_rear_wheel">
        <visual>
            <geometry>
                <cylinder length="0.26" radius="0.5"/>
            </geometry>
            <material name="black"/>
        </visual>
        <inertial>
            <mass value="2.0"/>
            <origin xyz="0 0 0" rpy="0 0 0"/>
            <inertia ixx="0.1" ixy="0.0" ixz="0.0" iyy="0.1" iyz="0.0" izz="0.1"/>
        </inertial>
    </link>
    <joint name="right_rear_wheel_joint" type="continuous">
        <parent link="base_link"/>
        <child link="right_rear_wheel"/>
        <origin xyz="-1.56 -1.16 -0.55" rpy="1.57 0.0 0.0"/>
        <axis xyz="0 0 1"/>
    </joint>
    <gazebo reference="right_rear_wheel">
        <material>Gazebo/Black</material>
    </gazebo>

    <!-- Left Front Wheel -->
    <link name="left_front_wheel">
        <visual>
            <geometry>
                <cylinder length="0.26" radius="0.5"/>
            </geometry>
            <material name="black"/>
        </visual>
        <inertial>
            <mass value="2.0"/>
            <origin xyz="0 0 0" rpy="0 0 0"/>
            <inertia ixx="0.1" ixy="0.0" ixz="0.0" iyy="0.1" iyz="0.0" izz="0.1"/>
        </inertial>
    </link>
    <joint name="left_front_wheel_joint" type="continuous">
        <parent link="base_link"/>
        <child link="left_front_wheel"/>
        <origin xyz="1.56 1.16 -0.55" rpy="-1.57 0.0 0.0"/>
        <axis xyz="0 0 1"/>
    </joint>
    <gazebo reference="left_front_wheel">
        <material>Gazebo/Black</material>
    </gazebo>

    <!-- Right Front Wheel -->
    <link name="right_front_wheel">
        <visual>
            <geometry>
                <cylinder length="0.26" radius="0.5"/>
            </geometry>
            <material name="black"/>
        </visual>
        <inertial>
            <mass value="2.0"/>
            <origin xyz="0 0 0" rpy="0 0 0"/>
            <inertia ixx="0.1" ixy="0.0" ixz="0.0" iyy="0.1" iyz="0.0" izz="0.1"/>
        </inertial>
    </link>
    <joint name="right_front_wheel_joint" type="continuous">
        <parent link="base_link"/>
        <child link="right_front_wheel"/>
        <origin xyz="1.56 -1.16 -0.55" rpy="1.57 0.0 0.0"/>
        <axis xyz="0 0 1"/>
    </joint>
    <gazebo reference="right_front_wheel">
        <material>Gazebo/Black</material>
    </gazebo>

    <!-- LIDAR Sensor -->
    <link name="laser_link">
        <visual>
            <geometry>
                <cylinder length="0.156" radius="0.152"/>
            </geometry>
            <material name="black"/>
        </visual>
        <inertial>
            <mass value="1.0"/>
            <origin xyz="0 0 0" rpy="0 0 0"/>
            <inertia ixx="0.01" ixy="0.0" ixz="0.0" iyy="0.01" iyz="0.0" izz="0.01"/>
        </inertial>
    </link>
    <joint name="laser_joint" type="fixed">
        <parent link="base_link"/>
        <child link="laser_link"/>
        <origin xyz="1.408 0.0 0.628" rpy="0.0 0.0 0.0"/>
    </joint>
    <gazebo reference="laser_link">
        <material>Gazebo/Black</material>
    </gazebo>

    <!-- Differential Drive Controller Plugin -->
    <gazebo>
        <plugin name="gazebo_ros_diff_drive" filename="libgazebo_ros_diff_drive.so">
            <robotNamespace>/</robotNamespace>
            <commandTopic>cmd_vel</commandTopic>
            <odometryTopic>odom</odometryTopic>
            <odometryFrame>odom</odometryFrame>
            <robotBaseFrame>base_link</robotBaseFrame>
            <leftJoint>left_front_wheel_joint</leftJoint>
            <rightJoint>right_front_wheel_joint</rightJoint>
            <wheelSeparation>0.34</wheelSeparation>
            <wheelDiameter>0.5</wheelDiameter>
            <wheelTorque>5.0</wheelTorque>
            <updateRate>100.0</updateRate>
            <publishOdomTF>true</publishOdomTF>
            <publishWheelTF>false</publishWheelTF>
            <publishWheelJointState>false</publishWheelJointState>
            <rosDebugLevel>na</rosDebugLevel>
            <wheelAcceleration>0</wheelAcceleration>
            <odometrySource>encoder</odometrySource>
            <publishTf>true</publishTf>
        </plugin>
    </gazebo>

    <!-- LIDAR Sensor Plugin -->
    <gazebo>
        <sensor type="ray" name="laser_sensor">
            <update_rate>30.0</update_rate>
            <pose>0 0 0.1 0 0 0</pose>
            <visualize>true</visualize>
            <ray>
                <scan>
                    <horizontal>
                        <samples>720</samples>
                        <resolution>1</resolution>
                        <min_angle>-3.14</min_angle>
                        <max_angle>3.14</max_angle>
                    </horizontal>
                </scan>
                <range>
                    <min>0.1</min>
                    <max>10.0</max>
                    <resolution>0.01</resolution>
                </range>
            </ray>
            <plugin name="gazebo_ros_laser_controller" filename="libgazebo_ros_laser.so">
                <robotNamespace>/</robotNamespace>
                <topicName>/scan</topicName>
                <frameName>laser_link</frameName>
            </plugin>
        </sensor>
    </gazebo>

</robot>