<?xml version="1.0"?>
<robot name="my_robot">

  
  
  
	<!-- MATERIALS -->
    <material name="black">
        <color rgba="0.0 0.0 0.0 0.75"/>
    </material>
    
    <material name="white">
        <color rgba="1.0 1.0 1.0 0.75"/>
    </material>
  
  
  
  
  	<!-- LINKS -->
    <link name="base_link">
        <visual>
            <geometry>
                <box size="0.78 0.504 0.278"/>
            </geometry>
            <origin xyz="0.0 0.0 0.139" rpy="0.0 0.0 0.0"/>   
            <material name="black"/> 
        </visual>
        <collision>
            <geometry>
                <box size="0.78 0.504 0.278"/>
            </geometry>
            <origin xyz="0.0 0.0 0.139" rpy="0.0 0.0 0.0"/>
        </collision>
        <inertial>
            <mass value="10.0"/>
            <inertia ixx="0.1" ixy="0.0" ixz="0.0" iyy="0.1" iyz="0.0" izz="0.1"/>
        </inertial>
    </link>

    <link name="upper_base_link">
        <visual>
            <geometry>
                <box size="0.4 0.504 0.382"/>
            </geometry>
            <origin xyz="0.0 0.0 0.0" rpy="0.0 0.0 0.0"/>
            <material name="black"/>            
        </visual>
        <collision>
            <geometry>
                <box size="0.4 0.504 0.382"/>
            </geometry>
            <origin xyz="0.0 0.0 0.0" rpy="0.0 0.0 0.0"/>          
        </collision>
        <inertial>
            <mass value="10.0"/>
            <inertia ixx="0.1" ixy="0.0" ixz="0.0" iyy="0.1" iyz="0.0" izz="0.1"/>
        </inertial>
    </link>
    
    <link name="back_rocker_link">
        <visual>
            <geometry>
                <box size="0.03 0.632 0.03"/>
            </geometry>
            <origin xyz="0.0 0.0 0.0" rpy="0.0 0.0 0.0"/>
            <material name="white"/>
        </visual>        
        <collision>
            <geometry>
                <box size="0.03 0.632 0.03"/>
            </geometry>
            <origin xyz="0.0 0.0 0.0" rpy="0.0 0.0 0.0"/>
        </collision>   
        <inertial>
            <mass value="1.0"/>
            <inertia ixx="0.01" ixy="0.0" ixz="0.0" iyy="0.01" iyz="0.0" izz="0.01"/>
        </inertial>     
    </link>
    
    <link name="back_rocker_left_link">
        <visual>
            <geometry>
                <box size="0.03 0.03 0.2"/>
            </geometry>
            <origin xyz="0.0 0.0 0.0" rpy="0.0 0.0 0.0"/>
            <material name="white"/>
        </visual>
        <collision>
            <geometry>
                <box size="0.03 0.03 0.2"/>
            </geometry>
            <origin xyz="0.0 0.0 0.0" rpy="0.0 0.0 0.0"/>
        </collision>
        <inertial>
            <mass value="1.0"/>
            <inertia ixx="0.01" ixy="0.0" ixz="0.0" iyy="0.01" iyz="0.0" izz="0.01"/>
        </inertial>
    </link>
    
    <link name="back_rocker_right_link">
        <visual>
            <geometry>
                <box size="0.03 0.03 0.2"/>
            </geometry>
            <origin xyz="0.0 0.0 0.0" rpy="0.0 0.0 0.0"/>
            <material name="white"/>
        </visual>
        <collision>
            <geometry>
                <box size="0.03 0.03 0.2"/>
            </geometry>
            <origin xyz="0.0 0.0 0.0" rpy="0.0 0.0 0.0"/>
        </collision>
        <inertial>
            <mass value="1.0"/>
            <inertia ixx="0.01" ixy="0.0" ixz="0.0" iyy="0.01" iyz="0.0" izz="0.01"/>
        </inertial>
    </link>   

    <link name="forward_left_front_rocker_link">
        <visual>
            <geometry>
                <box size="0.33 0.03 0.03"/>
            </geometry>
            <origin xyz="0.155 0.0 0.0" rpy="0.0 0.0 0.0"/>
            <material name="white"/>
        </visual>        
        <collision>
            <geometry>
                <box size="0.33 0.03 0.03"/>
            </geometry>
            <origin xyz="0.155 0.0 0.0" rpy="0.0 0.0 0.0"/>
        </collision>   
        <inertial>
            <mass value="1.0"/>
            <inertia ixx="0.01" ixy="0.0" ixz="0.0" iyy="0.01" iyz="0.0" izz="0.01"/>
        </inertial>     
    </link>

    <link name="backward_left_front_rocker_link">
        <visual>
            <geometry>
                <box size="0.3 0.03 0.03"/>
            </geometry>
            <origin xyz="-0.15 0.0 0.0" rpy="0.0 0.0 0.0"/>
            <material name="white"/>
        </visual>        
        <collision>
            <geometry>
                <box size="0.3 0.03 0.03"/>
            </geometry>
            <origin xyz="-0.15 0.0 0.0" rpy="0.0 0.0 0.0"/>
        </collision>   
        <inertial>
            <mass value="1.0"/>
            <inertia ixx="0.01" ixy="0.0" ixz="0.0" iyy="0.01" iyz="0.0" izz="0.01"/>
        </inertial>     
    </link>

    <link name="forward_right_front_rocker_link">
        <visual>
            <geometry>
                <box size="0.33 0.03 0.03"/>
            </geometry>
            <origin xyz="0.155 0.0 0.0" rpy="0.0 0.0 0.0"/>
            <material name="white"/>
        </visual>        
        <collision>
            <geometry>
                <box size="0.33 0.03 0.03"/>
            </geometry>
            <origin xyz="0.155 0.0 0.0" rpy="0.0 0.0 0.0"/>
        </collision>  
        <inertial>
            <mass value="1.0"/>
            <inertia ixx="0.01" ixy="0.0" ixz="0.0" iyy="0.01" iyz="0.0" izz="0.01"/>
        </inertial>      
    </link>

    <link name="backward_right_front_rocker_link">
        <visual>
            <geometry>
                <box size="0.3 0.03 0.03"/>
            </geometry>
            <origin xyz="-0.15 0.0 0.0" rpy="0.0 0.0 0.0"/>
            <material name="white"/>
        </visual>        
        <collision>
            <geometry>
                <box size="0.3 0.03 0.03"/>
            </geometry>
            <origin xyz="-0.15 0.0 0.0" rpy="0.0 0.0 0.0"/>
        </collision>  
        <inertial>
            <mass value="1.0"/>
            <inertia ixx="0.01" ixy="0.0" ixz="0.0" iyy="0.01" iyz="0.0" izz="0.01"/>
        </inertial>      
    </link>

    <link name="left_front_wheel_link">
        <visual>
            <geometry>
                <cylinder radius="0.127" length="0.055"/>
            </geometry>
            <origin xyz="0.0 0.0 0.0" rpy="0.0 0.0 0.0"/>
        </visual>
        <collision>
            <geometry>
                <cylinder radius="0.127" length="0.055"/>
            </geometry>
            <origin xyz="0.0 0.0 0.0" rpy="0.0 0.0 0.0"/>
        </collision>
        <inertial>
            <mass value="1.0"/>
            <origin xyz="0.0 0.0 0.0" rpy="0.0 0.0 0.0"/>
            <inertia ixx="0.001" ixy="0.0" ixz="0.0" iyy="0.001" iyz="0.0" izz="0.001"/>
        </inertial>
    </link>

    <link name="right_front_wheel_link">
        <visual>
            <geometry>
                <cylinder radius="0.127" length="0.055"/>
            </geometry>
            <origin xyz="0.0 0.0 0.0" rpy="0.0 0.0 0.0"/>
        </visual>
        <collision>
            <geometry>
                <cylinder radius="0.127" length="0.055"/>
            </geometry>
            <origin xyz="0.0 0.0 0.0" rpy="0.0 0.0 0.0"/>
        </collision>
        <inertial>
            <mass value="1.0"/>
            <origin xyz="0.0 0.0 0.0" rpy="0.0 0.0 0.0"/>
            <inertia ixx="0.001" ixy="0.0" ixz="0.0" iyy="0.001" iyz="0.0" izz="0.001"/>
        </inertial>
    </link>

    <link name="left_back_wheel_link">
        <visual>
            <geometry>
                <cylinder radius="0.127" length="0.055"/>
            </geometry>
            <origin xyz="0.0 0.0 0.0" rpy="0.0 0.0 0.0"/>
        </visual>
        <collision>
            <geometry>
                <cylinder radius="0.127" length="0.055"/>
            </geometry>
            <origin xyz="0.0 0.0 0.0" rpy="0.0 0.0 0.0"/>
        </collision>
        <inertial>
            <mass value="1.0"/>
            <origin xyz="0.0 0.0 0.0" rpy="0.0 0.0 0.0"/>
            <inertia ixx="0.001" ixy="0.0" ixz="0.0" iyy="0.001" iyz="0.0" izz="0.001"/>
        </inertial>
    </link>

    <link name="right_back_wheel_link">
        <visual>
            <geometry>
                <cylinder radius="0.127" length="0.055"/>
            </geometry>
            <origin xyz="0.0 0.0 0.0" rpy="0.0 0.0 0.0"/>
        </visual>
        <collision>
            <geometry>
                <cylinder radius="0.127" length="0.055"/>
            </geometry>
            <origin xyz="0.0 0.0 0.0" rpy="0.0 0.0 0.0"/>
        </collision>
        <inertial>
            <mass value="1.0"/>
            <origin xyz="0.0 0.0 0.0" rpy="0.0 0.0 0.0"/>
            <inertia ixx="0.001" ixy="0.0" ixz="0.0" iyy="0.001" iyz="0.0" izz="0.001"/>
        </inertial>
    </link>

    <link name="left_pneumatic_wheel_link">
        <visual>
            <geometry>
                <cylinder radius="0.127" length="0.055"/>
            </geometry>
            <origin xyz="0.0 0.0 0.0" rpy="0.0 0.0 0.0"/>
        </visual>
        <collision>
            <geometry>
                <cylinder radius="0.127" length="0.055"/>
            </geometry>
            <origin xyz="0.0 0.0 0.0" rpy="0.0 0.0 0.0"/>
        </collision>
        <inertial>
            <mass value="1.0"/>
            <origin xyz="0.0 0.0 0.0" rpy="0.0 0.0 0.0"/>
            <inertia ixx="0.001" ixy="0.0" ixz="0.0" iyy="0.001" iyz="0.0" izz="0.001"/>
        </inertial>
    </link>

    <link name="right_pneumatic_wheel_link">
        <visual>
            <geometry>
                <cylinder radius="0.127" length="0.055"/>
            </geometry>
            <origin xyz="0.0 0.0 0.0" rpy="0.0 0.0 0.0"/>
        </visual>
        <collision>
            <geometry>
                <cylinder radius="0.127" length="0.055"/>
            </geometry>
            <origin xyz="0.0 0.0 0.0" rpy="0.0 0.0 0.0"/>
        </collision>
        <inertial>
            <mass value="1.0"/>
            <origin xyz="0.0 0.0 0.0" rpy="0.0 0.0 0.0"/>
            <inertia ixx="0.001" ixy="0.0" ixz="0.0" iyy="0.001" iyz="0.0" izz="0.001"/>
        </inertial>
    </link>

    <link name="rplidar_link">
        <visual>
            <geometry>
                <cylinder radius="0.038" length="0.041"/>
            </geometry>
            <origin xyz="0.0 0.0 0.0" rpy="0.0 0.0 0.0"/>
        </visual>
        <collision>
            <geometry>
                <cylinder radius="0.038" length="0.041"/>
            </geometry>
            <origin xyz="0.0 0.0 0.0" rpy="0.0 0.0 0.0"/>
        </collision>
        <inertial>
            <mass value="0.1"/>
            <inertia ixx="0.000063" ixy="0" ixz="0" iyy="0.000063" iyz="0" izz="0.000125"/>
        </inertial>
    </link>

    <link name="imu_link">
        <visual>
            <geometry>
                <box size="0.015 0.02 0.001"/>
            </geometry>
            <origin xyz="0.0 0.0 0.0" rpy="0.0 0.0 0.0"/>
        </visual>    
        <collision>
            <geometry>
                <box size="0.015 0.02 0.001"/>
            </geometry>
            <origin xyz="0.0 0.0 0.0" rpy="0.0 0.0 0.0"/>
        </collision>    
        <inertial>
            <mass value="0.1"/>
            <inertia ixx="0.000063" ixy="0" ixz="0" iyy="0.000063" iyz="0" izz="0.000125"/>
        </inertial>
    </link>



    
  	<!-- JOINTS / TRANSFORMS -->
    <joint name="base_upper_base_joint" type="fixed">
        <parent link="base_link"/>
        <child link="upper_base_link"/>
        <origin xyz="-0.19 0.0 0.469" rpy="0.0 0.0 0.0"/>
    </joint>

    <joint name="base_back_rocker_joint" type="revolute">    
        <parent link="base_link"/>
        <child link="back_rocker_link"/>
        <origin xyz="-0.425 0.0 -0.028" rpy="0.0 0.0 0.0"/>    <!-- TODO -0.028  actual: -0.03 -->
        <axis xyz="1.0 0.0 0.0"/>
        <limit lower="-0.349" upper="0.349" effort="0.0" velocity="0.0"/>
    </joint>

    <joint name="back_rocker_back_rocker_left_joint" type="fixed">
        <parent link="back_rocker_link"/>
        <child link="back_rocker_left_link"/>
        <origin xyz="-0.03 0.301 -0.085" rpy="0.0 0.0 0.0"/>
    </joint>

    <joint name="back_rocker_back_rocker_right_joint" type="fixed">
        <parent link="back_rocker_link"/>
        <child link="back_rocker_right_link"/>
        <origin xyz="-0.03 -0.301 -0.085" rpy="0.0 0.0 0.0"/>
    </joint>

    <joint name="base_forward_left_front_rocker_joint" type="revolute">
        <parent link="base_link"/>
        <child link="forward_left_front_rocker_link"/>
        <origin xyz="0.225 0.282 0.015" rpy="0.0 0.785 0.0"/>
        <axis xyz="0.0 1.0 0.0"/>
        <limit lower="-0.523" upper="0.523" effort="0.0" velocity="0.0"/>
    </joint>

    <joint name="forward_left_front_rocker_backward_left_front_rocker_joint" type="fixed">
        <parent link="forward_left_front_rocker_link"/>
        <child link="backward_left_front_rocker_link"/>
        <origin xyz="0.005 0.0 -0.015" rpy="0.0 -1.57 0.0"/>
    </joint>

    <joint name="base_forward_right_front_rocker_joint" type="revolute">
        <parent link="base_link"/>
        <child link="forward_right_front_rocker_link"/>
        <origin xyz="0.225 -0.282 0.015" rpy="0.0 0.785 0.0"/>
        <axis xyz="0.0 1.0 0.0"/>
        <limit lower="-0.523" upper="0.523" effort="0.0" velocity="0.0"/>
    </joint>

    <joint name="forward_right_front_rocker_backward_right_front_rocker_joint" type="fixed">
        <parent link="forward_right_front_rocker_link"/>
        <child link="backward_right_front_rocker_link"/>
        <origin xyz="0.005 0.0 -0.015" rpy="0.0 -1.57 0.0"/>
    </joint>
    
    <joint name="forward_left_front_rocker_left_front_wheel_joint" type="continuous">
        <parent link="forward_left_front_rocker_link"/>
        <child link="left_front_wheel_link"/>
        <origin xyz="0.31 0.0825 0.0" rpy="-1.57 0.0 0.0"/>
        <axis xyz="0.0 0.0 1.0"/>
    </joint>
    
    <joint name="forward_right_front_rocker_right_front_wheel_joint" type="continuous">
        <parent link="forward_right_front_rocker_link"/>
        <child link="right_front_wheel_link"/>
        <origin xyz="0.31 -0.0825 0.0" rpy="1.57 0.0 0.0"/>
        <axis xyz="0.0 0.0 -1.0"/>
    </joint>

    <joint name="back_rocker_left_left_back_wheel_joint" type="continuous">
        <parent link="back_rocker_left_link"/>
        <child link="left_back_wheel_link"/>
        <origin xyz="0.0 0.0825 -0.09" rpy="1.57 0.0 0.0"/>
        <axis xyz="0.0 0.0 -1.0"/>
    </joint>

    <joint name="back_rocker_right_right_back_wheel_joint" type="continuous">
        <parent link="back_rocker_right_link"/>
        <child link="right_back_wheel_link"/>
        <origin xyz="0.0 -0.0825 -0.09" rpy="-1.57 0.0 0.0"/>
        <axis xyz="0.0 0.0 1.0"/>
    </joint>
    
    <joint name="backward_left_front_rocker_left_pneumatic_wheel_joint" type="continuous">
        <parent link="backward_left_front_rocker_link"/>
        <child link="left_pneumatic_wheel_link"/>
        <origin xyz="-0.29 0.0555 0.0" rpy="-1.57 0.0 0.0"/>
        <axis xyz="0.0 0.0 1.0"/>
    </joint>
    
    <joint name="backward_right_front_rocker_right_pneumatic_wheel_joint" type="continuous">
        <parent link="backward_right_front_rocker_link"/>
        <child link="right_pneumatic_wheel_link"/>
        <origin xyz="-0.29 -0.0555 0.0" rpy="1.57 0.0 0.0"/>
        <axis xyz="0.0 0.0 -1.0"/>
    </joint>

    <joint name="base_rplidar_joint" type="fixed">
        <parent link="base_link"/>
        <child link="rplidar_link"/>
        <origin xyz="0.29 0.0 0.303" rpy="0.0 0.0 0.0"/>
    </joint>

    <joint name="base_imu_joint" type="fixed">
        <parent link="base_link"/>
        <child link="imu_link"/>
        <origin xyz="0.0 0.0 0.66" rpy="0.0 0.0 0.0"/>
    </joint>




    <!-- COLORS -->
    <gazebo reference="base_link">
        <material> Gazebo/DarkGrey </material>
    </gazebo>

    <gazebo reference="upper_base_link">
        <material> Gazebo/DarkGrey </material>
    </gazebo>

    <gazebo reference="back_rocker_link">
        <material> Gazebo/ZincYellow </material>
    </gazebo>

    <gazebo reference="back_rocker_left_link">
        <material> Gazebo/ZincYellow </material>
    </gazebo>

    <gazebo reference="back_rocker_right_link">
        <material> Gazebo/ZincYellow </material>
    </gazebo>

    <gazebo reference="forward_left_front_rocker_link">
        <material> Gazebo/ZincYellow </material>
    </gazebo>

    <gazebo reference="backward_left_front_rocker_link">
        <material> Gazebo/ZincYellow </material>
    </gazebo>

    <gazebo reference="forward_right_front_rocker_link">
        <material> Gazebo/ZincYellow </material>
    </gazebo>

    <gazebo reference="backward_right_front_rocker_link">
        <material> Gazebo/ZincYellow </material>
    </gazebo>

    <gazebo reference="left_front_wheel_link">
        <material> Gazebo/Black </material>
    </gazebo>

    <gazebo reference="right_front_wheel_link">
        <material> Gazebo/Black </material>
    </gazebo>

    <gazebo reference="left_back_wheel_link">
        <material> Gazebo/Black </material>
    </gazebo>

    <gazebo reference="right_back_wheel_link">
        <material> Gazebo/Black </material>
    </gazebo>

    <gazebo reference="left_pneumatic_wheel_link">
        <material> Gazebo/Black </material>
    </gazebo>

    <gazebo reference="right_pneumatic_wheel_link">
        <material> Gazebo/Black </material>
    </gazebo>

    <gazebo reference="rplidar_link">
        <material> Gazebo/RedGlow </material>
    </gazebo>

    <gazebo reference="imu_link">
        <material> Gazebo/RedGlow </material>
    </gazebo>




    <!-- PLUGINS -->
    <gazebo>
        <plugin name="skid_steer_drive_controller" filename="libgazebo_ros_skid_steer_drive.so">
            <updateRate>100.0</updateRate>
            <robotNamespace>/</robotNamespace>
            <leftFrontJoint>forward_left_front_rocker_left_front_wheel_joint</leftFrontJoint>
            <rightFrontJoint>forward_right_front_rocker_right_front_wheel_joint</rightFrontJoint>
            <leftRearJoint>back_rocker_left_left_back_wheel_joint</leftRearJoint>
            <rightRearJoint>back_rocker_right_right_back_wheel_joint</rightRearJoint>
            <wheelSeparation>0.729</wheelSeparation>
            <wheelDiameter>0.254</wheelDiameter>
            <robotBaseFrame>base_link</robotBaseFrame>
            <torque>20</torque>
            <topicName>cmd_vel</topicName>
            <broadcastTF>true</broadcastTF>
        </plugin>
    </gazebo>

    <gazebo reference="rplidar_link">
        <sensor type="ray" name="head_hokuyo_sensor">
        <pose>0 0 0 0 0 0</pose>
        <visualize>true</visualize>
        <update_rate>40</update_rate>
        <ray>
            <scan>
            <horizontal>
                <samples>360</samples>
                <resolution>1</resolution>
                <min_angle>-1.3089</min_angle>
                <max_angle>1.3089</max_angle>
            </horizontal>
            </scan>
            <range>
            <min>0.10</min>
            <max>30.0</max>
            <resolution>0.01</resolution>
            </range>
            <noise>
            <type>gaussian</type>
            <mean>0.0</mean>
            <stddev>0.01</stddev>
            </noise>
        </ray>
        <plugin name="gazebo_ros_head_hokuyo_controller" filename="libgazebo_ros_laser.so">
            <topicName>/scan</topicName>
            <frameName>rplidar_link</frameName>
        </plugin>
        </sensor>
    </gazebo>

    <gazebo reference="imu_link">
        <gravity>true</gravity>
        <sensor name="imu_sensor" type="imu">
        <always_on>true</always_on>
        <update_rate>100</update_rate>
        <visualize>true</visualize>
        <topic>__default_topic__</topic>
        <plugin filename="libgazebo_ros_imu_sensor.so" name="imu_plugin">
            <topicName>imu</topicName>
            <bodyName>imu_link</bodyName>
            <updateRateHZ>10.0</updateRateHZ>
            <gaussianNoise>0.0</gaussianNoise>
            <xyzOffset>0 0 0</xyzOffset>
            <rpyOffset>0 0 0</rpyOffset>
            <frameName>imu_link</frameName>
            <initialOrientationAsReference>false</initialOrientationAsReference>    <!-- False, means takes global reference frame -->
        </plugin>
        <pose>0 0 0 0 0 0</pose>
        </sensor>
    </gazebo>
  
</robot>